2017-06-18 11:51:52,806 INFO org.apache.hadoop.yarn.server.resourcemanager.ResourceManager: STARTUP_MSG: 
/************************************************************
STARTUP_MSG: Starting ResourceManager
STARTUP_MSG:   host = master/192.168.56.178
STARTUP_MSG:   args = []
STARTUP_MSG:   version = 2.6.5
STARTUP_MSG:   build = https://github.com/apache/hadoop.git -r e8c9fe0b4c252caf2ebf1464220599650f119997; compiled by 'sjlee' on 2016-10-02T23:43Z
STARTUP_MSG:   java = 1.8.0_25
************************************************************/
2017-06-18 11:51:52,853 INFO org.apache.hadoop.yarn.server.resourcemanager.ResourceManager: registered UNIX signal handlers for [TERM, HUP, INT]
2017-06-18 11:51:54,313 INFO org.apache.hadoop.conf.Configuration: found resource core-site.xml at file:/usr/local/bigdata/hadoop/hadoop-2.6.5/etc/hadoop/core-site.xml
2017-06-18 11:51:54,606 WARN org.apache.hadoop.util.NativeCodeLoader: Unable to load native-hadoop library for your platform... using builtin-java classes where applicable
2017-06-18 11:51:54,819 INFO org.apache.hadoop.security.Groups: clearing userToGroupsMap cache
2017-06-18 11:51:55,270 INFO org.apache.hadoop.conf.Configuration: found resource yarn-site.xml at file:/usr/local/bigdata/hadoop/hadoop-2.6.5/etc/hadoop/yarn-site.xml
2017-06-18 11:51:56,430 INFO org.apache.hadoop.yarn.event.AsyncDispatcher: Registering class org.apache.hadoop.yarn.server.resourcemanager.RMFatalEventType for class org.apache.hadoop.yarn.server.resourcemanager.ResourceManager$RMFatalEventDispatcher
2017-06-18 11:51:57,698 INFO org.apache.hadoop.yarn.server.resourcemanager.security.NMTokenSecretManagerInRM: NMTokenKeyRollingInterval: 86400000ms and NMTokenKeyActivationDelay: 900000ms
2017-06-18 11:51:57,719 INFO org.apache.hadoop.yarn.server.resourcemanager.security.RMContainerTokenSecretManager: ContainerTokenKeyRollingInterval: 86400000ms and ContainerTokenKeyActivationDelay: 900000ms
2017-06-18 11:51:57,768 INFO org.apache.hadoop.yarn.server.resourcemanager.security.AMRMTokenSecretManager: AMRMTokenKeyRollingInterval: 86400000ms and AMRMTokenKeyActivationDelay: 900000 ms
2017-06-18 11:51:57,968 INFO org.apache.hadoop.yarn.event.AsyncDispatcher: Registering class org.apache.hadoop.yarn.server.resourcemanager.recovery.RMStateStoreEventType for class org.apache.hadoop.yarn.server.resourcemanager.recovery.RMStateStore$ForwardingEventHandler
2017-06-18 11:51:57,972 INFO org.apache.hadoop.yarn.event.AsyncDispatcher: Registering class org.apache.hadoop.yarn.server.resourcemanager.NodesListManagerEventType for class org.apache.hadoop.yarn.server.resourcemanager.NodesListManager
2017-06-18 11:51:57,972 INFO org.apache.hadoop.yarn.server.resourcemanager.ResourceManager: Using Scheduler: org.apache.hadoop.yarn.server.resourcemanager.scheduler.capacity.CapacityScheduler
2017-06-18 11:51:58,056 INFO org.apache.hadoop.yarn.event.AsyncDispatcher: Registering class org.apache.hadoop.yarn.server.resourcemanager.scheduler.event.SchedulerEventType for class org.apache.hadoop.yarn.server.resourcemanager.ResourceManager$SchedulerEventDispatcher
2017-06-18 11:51:58,070 INFO org.apache.hadoop.yarn.event.AsyncDispatcher: Registering class org.apache.hadoop.yarn.server.resourcemanager.rmapp.RMAppEventType for class org.apache.hadoop.yarn.server.resourcemanager.ResourceManager$ApplicationEventDispatcher
2017-06-18 11:51:58,076 INFO org.apache.hadoop.yarn.event.AsyncDispatcher: Registering class org.apache.hadoop.yarn.server.resourcemanager.rmapp.attempt.RMAppAttemptEventType for class org.apache.hadoop.yarn.server.resourcemanager.ResourceManager$ApplicationAttemptEventDispatcher
2017-06-18 11:51:58,078 INFO org.apache.hadoop.yarn.event.AsyncDispatcher: Registering class org.apache.hadoop.yarn.server.resourcemanager.rmnode.RMNodeEventType for class org.apache.hadoop.yarn.server.resourcemanager.ResourceManager$NodeEventDispatcher
2017-06-18 11:51:58,492 INFO org.apache.hadoop.metrics2.impl.MetricsConfig: loaded properties from hadoop-metrics2.properties
2017-06-18 11:51:59,031 INFO org.apache.hadoop.metrics2.impl.MetricsSystemImpl: Scheduled snapshot period at 10 second(s).
2017-06-18 11:51:59,031 INFO org.apache.hadoop.metrics2.impl.MetricsSystemImpl: ResourceManager metrics system started
2017-06-18 11:51:59,149 INFO org.apache.hadoop.yarn.event.AsyncDispatcher: Registering class org.apache.hadoop.yarn.server.resourcemanager.RMAppManagerEventType for class org.apache.hadoop.yarn.server.resourcemanager.RMAppManager
2017-06-18 11:51:59,226 INFO org.apache.hadoop.yarn.event.AsyncDispatcher: Registering class org.apache.hadoop.yarn.server.resourcemanager.amlauncher.AMLauncherEventType for class org.apache.hadoop.yarn.server.resourcemanager.amlauncher.ApplicationMasterLauncher
2017-06-18 11:51:59,251 INFO org.apache.hadoop.yarn.server.resourcemanager.RMNMInfo: Registered RMNMInfo MBean
2017-06-18 11:51:59,267 INFO org.apache.hadoop.util.HostsFileReader: Refreshing hosts (include/exclude) list
2017-06-18 11:51:59,295 INFO org.apache.hadoop.conf.Configuration: found resource capacity-scheduler.xml at file:/usr/local/bigdata/hadoop/hadoop-2.6.5/etc/hadoop/capacity-scheduler.xml
2017-06-18 11:51:59,810 INFO org.apache.hadoop.yarn.server.resourcemanager.scheduler.capacity.ParentQueue: root, capacity=1.0, asboluteCapacity=1.0, maxCapacity=1.0, asboluteMaxCapacity=1.0, state=RUNNING, acls=SUBMIT_APPLICATIONS:*ADMINISTER_QUEUE:*, labels=*,
, reservationsContinueLooking=true
2017-06-18 11:51:59,811 INFO org.apache.hadoop.yarn.server.resourcemanager.scheduler.capacity.ParentQueue: Initialized parent-queue root name=root, fullname=root
2017-06-18 11:51:59,945 INFO org.apache.hadoop.yarn.server.resourcemanager.scheduler.capacity.LeafQueue: Initializing default
capacity = 1.0 [= (float) configuredCapacity / 100 ]
asboluteCapacity = 1.0 [= parentAbsoluteCapacity * capacity ]
maxCapacity = 1.0 [= configuredMaxCapacity ]
absoluteMaxCapacity = 1.0 [= 1.0 maximumCapacity undefined, (parentAbsoluteMaxCapacity * maximumCapacity) / 100 otherwise ]
userLimit = 100 [= configuredUserLimit ]
userLimitFactor = 1.0 [= configuredUserLimitFactor ]
maxApplications = 10000 [= configuredMaximumSystemApplicationsPerQueue or (int)(configuredMaximumSystemApplications * absoluteCapacity)]
maxApplicationsPerUser = 10000 [= (int)(maxApplications * (userLimit / 100.0f) * userLimitFactor) ]
usedCapacity = 0.0 [= usedResourcesMemory / (clusterResourceMemory * absoluteCapacity)]
absoluteUsedCapacity = 0.0 [= usedResourcesMemory / clusterResourceMemory]
maxAMResourcePerQueuePercent = 0.1 [= configuredMaximumAMResourcePercent ]
minimumAllocationFactor = 0.875 [= (float)(maximumAllocationMemory - minimumAllocationMemory) / maximumAllocationMemory ]
numContainers = 0 [= currentNumContainers ]
state = RUNNING [= configuredState ]
acls = SUBMIT_APPLICATIONS:*ADMINISTER_QUEUE:* [= configuredAcls ]
nodeLocalityDelay = 40
labels=*,
nodeLocalityDelay = 40
reservationsContinueLooking = true

2017-06-18 11:51:59,954 INFO org.apache.hadoop.yarn.server.resourcemanager.scheduler.capacity.CapacityScheduler: Initialized queue: default: capacity=1.0, absoluteCapacity=1.0, usedResources=<memory:0, vCores:0>, usedCapacity=0.0, absoluteUsedCapacity=0.0, numApps=0, numContainers=0
2017-06-18 11:51:59,955 INFO org.apache.hadoop.yarn.server.resourcemanager.scheduler.capacity.CapacityScheduler: Initialized queue: root: numChildQueue= 1, capacity=1.0, absoluteCapacity=1.0, usedResources=<memory:0, vCores:0>usedCapacity=0.0, numApps=0, numContainers=0
2017-06-18 11:51:59,957 INFO org.apache.hadoop.yarn.server.resourcemanager.scheduler.capacity.CapacityScheduler: Initialized root queue root: numChildQueue= 1, capacity=1.0, absoluteCapacity=1.0, usedResources=<memory:0, vCores:0>usedCapacity=0.0, numApps=0, numContainers=0
2017-06-18 11:51:59,957 INFO org.apache.hadoop.yarn.server.resourcemanager.scheduler.capacity.CapacityScheduler: Initialized queue mappings, override: false
2017-06-18 11:51:59,969 INFO org.apache.hadoop.yarn.server.resourcemanager.scheduler.capacity.CapacityScheduler: Initialized CapacityScheduler with calculator=class org.apache.hadoop.yarn.util.resource.DefaultResourceCalculator, minimumAllocation=<<memory:1024, vCores:1>>, maximumAllocation=<<memory:8192, vCores:32>>, asynchronousScheduling=false, asyncScheduleInterval=5ms
2017-06-18 11:52:00,071 INFO org.apache.hadoop.yarn.server.resourcemanager.metrics.SystemMetricsPublisher: YARN system metrics publishing service is not enabled
2017-06-18 11:52:00,071 INFO org.apache.hadoop.yarn.server.resourcemanager.ResourceManager: Transitioning to active state
2017-06-18 11:52:00,223 INFO org.apache.hadoop.yarn.server.resourcemanager.security.RMContainerTokenSecretManager: Rolling master-key for container-tokens
2017-06-18 11:52:00,224 INFO org.apache.hadoop.yarn.server.resourcemanager.security.NMTokenSecretManagerInRM: Rolling master-key for nm-tokens
2017-06-18 11:52:00,226 INFO org.apache.hadoop.security.token.delegation.AbstractDelegationTokenSecretManager: Updating the current master key for generating delegation tokens
2017-06-18 11:52:00,227 INFO org.apache.hadoop.yarn.server.resourcemanager.security.RMDelegationTokenSecretManager: storing master key with keyID 1
2017-06-18 11:52:00,261 INFO org.apache.hadoop.security.token.delegation.AbstractDelegationTokenSecretManager: Starting expired delegation token remover thread, tokenRemoverScanInterval=60 min(s)
2017-06-18 11:52:00,263 INFO org.apache.hadoop.security.token.delegation.AbstractDelegationTokenSecretManager: Updating the current master key for generating delegation tokens
2017-06-18 11:52:00,264 INFO org.apache.hadoop.yarn.server.resourcemanager.security.RMDelegationTokenSecretManager: storing master key with keyID 2
2017-06-18 11:52:00,642 INFO org.apache.hadoop.ipc.CallQueueManager: Using callQueue: class java.util.concurrent.LinkedBlockingQueue queueCapacity: 5000
2017-06-18 11:52:00,725 INFO org.apache.hadoop.ipc.Server: Starting Socket Reader #1 for port 8031
2017-06-18 11:52:00,832 INFO org.apache.hadoop.yarn.factories.impl.pb.RpcServerFactoryPBImpl: Adding protocol org.apache.hadoop.yarn.server.api.ResourceTrackerPB to the server
2017-06-18 11:52:00,837 INFO org.apache.hadoop.ipc.Server: IPC Server Responder: starting
2017-06-18 11:52:00,866 INFO org.apache.hadoop.ipc.Server: IPC Server listener on 8031: starting
2017-06-18 11:52:01,069 INFO org.apache.hadoop.ipc.CallQueueManager: Using callQueue: class java.util.concurrent.LinkedBlockingQueue queueCapacity: 5000
2017-06-18 11:52:01,093 INFO org.apache.hadoop.ipc.Server: Starting Socket Reader #1 for port 8030
2017-06-18 11:52:01,147 INFO org.apache.hadoop.yarn.factories.impl.pb.RpcServerFactoryPBImpl: Adding protocol org.apache.hadoop.yarn.api.ApplicationMasterProtocolPB to the server
2017-06-18 11:52:01,152 INFO org.apache.hadoop.ipc.Server: IPC Server Responder: starting
2017-06-18 11:52:01,154 INFO org.apache.hadoop.ipc.Server: IPC Server listener on 8030: starting
2017-06-18 11:52:01,564 INFO org.apache.hadoop.ipc.CallQueueManager: Using callQueue: class java.util.concurrent.LinkedBlockingQueue queueCapacity: 5000
2017-06-18 11:52:01,575 INFO org.apache.hadoop.ipc.Server: Starting Socket Reader #1 for port 8032
2017-06-18 11:52:01,589 INFO org.apache.hadoop.yarn.factories.impl.pb.RpcServerFactoryPBImpl: Adding protocol org.apache.hadoop.yarn.api.ApplicationClientProtocolPB to the server
2017-06-18 11:52:01,592 INFO org.apache.hadoop.ipc.Server: IPC Server Responder: starting
2017-06-18 11:52:01,750 INFO org.apache.hadoop.yarn.server.resourcemanager.ResourceManager: Transitioned to active state
2017-06-18 11:52:01,751 INFO org.apache.hadoop.ipc.Server: IPC Server listener on 8032: starting
2017-06-18 11:52:02,188 INFO org.mortbay.log: Logging to org.slf4j.impl.Log4jLoggerAdapter(org.mortbay.log) via org.mortbay.log.Slf4jLog
2017-06-18 11:52:02,209 INFO org.apache.hadoop.http.HttpRequestLog: Http request log for http.requests.resourcemanager is not defined
2017-06-18 11:52:02,307 INFO org.apache.hadoop.http.HttpServer2: Added global filter 'safety' (class=org.apache.hadoop.http.HttpServer2$QuotingInputFilter)
2017-06-18 11:52:02,359 INFO org.apache.hadoop.http.HttpServer2: Added filter RMAuthenticationFilter (class=org.apache.hadoop.yarn.server.security.http.RMAuthenticationFilter) to context cluster
2017-06-18 11:52:02,366 INFO org.apache.hadoop.http.HttpServer2: Added filter RMAuthenticationFilter (class=org.apache.hadoop.yarn.server.security.http.RMAuthenticationFilter) to context logs
2017-06-18 11:52:02,366 INFO org.apache.hadoop.http.HttpServer2: Added filter RMAuthenticationFilter (class=org.apache.hadoop.yarn.server.security.http.RMAuthenticationFilter) to context static
2017-06-18 11:52:02,369 INFO org.apache.hadoop.http.HttpServer2: Added filter static_user_filter (class=org.apache.hadoop.http.lib.StaticUserWebFilter$StaticUserFilter) to context cluster
2017-06-18 11:52:02,369 INFO org.apache.hadoop.http.HttpServer2: Added filter static_user_filter (class=org.apache.hadoop.http.lib.StaticUserWebFilter$StaticUserFilter) to context logs
2017-06-18 11:52:02,369 INFO org.apache.hadoop.http.HttpServer2: Added filter static_user_filter (class=org.apache.hadoop.http.lib.StaticUserWebFilter$StaticUserFilter) to context static
2017-06-18 11:52:02,397 INFO org.apache.hadoop.http.HttpServer2: adding path spec: /cluster/*
2017-06-18 11:52:02,397 INFO org.apache.hadoop.http.HttpServer2: adding path spec: /ws/*
2017-06-18 11:52:02,446 INFO org.apache.hadoop.http.HttpServer2: Jetty bound to port 8088
2017-06-18 11:52:02,450 INFO org.mortbay.log: jetty-6.1.26
2017-06-18 11:52:02,604 INFO org.mortbay.log: Extract jar:file:/usr/local/bigdata/hadoop/hadoop-2.6.5/share/hadoop/yarn/hadoop-yarn-common-2.6.5.jar!/webapps/cluster to /tmp/Jetty_0_0_0_0_8088_cluster____u0rgz3/webapp
2017-06-18 11:52:04,385 INFO org.apache.hadoop.security.token.delegation.AbstractDelegationTokenSecretManager: Updating the current master key for generating delegation tokens
2017-06-18 11:52:04,391 INFO org.apache.hadoop.security.token.delegation.AbstractDelegationTokenSecretManager: Starting expired delegation token remover thread, tokenRemoverScanInterval=60 min(s)
2017-06-18 11:52:04,393 INFO org.apache.hadoop.security.token.delegation.AbstractDelegationTokenSecretManager: Updating the current master key for generating delegation tokens
2017-06-18 11:52:04,587 INFO org.apache.hadoop.security.token.delegation.AbstractDelegationTokenSecretManager: Updating the current master key for generating delegation tokens
2017-06-18 11:52:04,591 INFO org.apache.hadoop.security.token.delegation.AbstractDelegationTokenSecretManager: Starting expired delegation token remover thread, tokenRemoverScanInterval=60 min(s)
2017-06-18 11:52:04,595 INFO org.apache.hadoop.security.token.delegation.AbstractDelegationTokenSecretManager: Updating the current master key for generating delegation tokens
2017-06-18 11:52:04,595 INFO org.apache.hadoop.security.token.delegation.AbstractDelegationTokenSecretManager: Updating the current master key for generating delegation tokens
2017-06-18 11:52:04,599 INFO org.apache.hadoop.security.token.delegation.AbstractDelegationTokenSecretManager: Starting expired delegation token remover thread, tokenRemoverScanInterval=60 min(s)
2017-06-18 11:52:04,605 INFO org.apache.hadoop.security.token.delegation.AbstractDelegationTokenSecretManager: Updating the current master key for generating delegation tokens
2017-06-18 11:52:04,626 INFO org.mortbay.log: Started HttpServer2$SelectChannelConnectorWithSafeStartup@0.0.0.0:8088
2017-06-18 11:52:04,626 INFO org.apache.hadoop.yarn.webapp.WebApps: Web app /cluster started at 8088
2017-06-18 11:52:07,211 INFO org.apache.hadoop.yarn.webapp.WebApps: Registered webapp guice modules
2017-06-18 11:52:07,425 INFO org.apache.hadoop.ipc.CallQueueManager: Using callQueue: class java.util.concurrent.LinkedBlockingQueue queueCapacity: 100
2017-06-18 11:52:07,431 INFO org.apache.hadoop.ipc.Server: Starting Socket Reader #1 for port 8033
2017-06-18 11:52:07,436 INFO org.apache.hadoop.yarn.factories.impl.pb.RpcServerFactoryPBImpl: Adding protocol org.apache.hadoop.yarn.server.api.ResourceManagerAdministrationProtocolPB to the server
2017-06-18 11:52:07,440 INFO org.apache.hadoop.ipc.Server: IPC Server Responder: starting
2017-06-18 11:52:07,440 INFO org.apache.hadoop.ipc.Server: IPC Server listener on 8033: starting
2017-06-18 11:52:09,496 INFO org.apache.hadoop.yarn.util.RackResolver: Resolved master to /default-rack
2017-06-18 11:52:09,502 INFO org.apache.hadoop.yarn.server.resourcemanager.rmnode.RMNodeImpl: master:37691 Node Transitioned from NEW to RUNNING
2017-06-18 11:52:09,502 INFO org.apache.hadoop.yarn.server.resourcemanager.ResourceTrackerService: NodeManager from node master(cmPort: 37691 httpPort: 8042) registered with capability: <memory:8192, vCores:8>, assigned nodeId master:37691
2017-06-18 11:52:09,509 INFO org.apache.hadoop.yarn.server.resourcemanager.scheduler.capacity.CapacityScheduler: Added node master:37691 clusterResource: <memory:8192, vCores:8>
2017-06-18 11:54:54,732 INFO org.apache.hadoop.yarn.server.resourcemanager.ClientRMService: Allocated new applicationId: 1
2017-06-18 11:58:25,305 INFO org.apache.hadoop.yarn.server.resourcemanager.ClientRMService: Allocated new applicationId: 2
2017-06-18 11:58:28,800 INFO org.apache.hadoop.yarn.server.resourcemanager.rmapp.RMAppImpl: Storing application with id application_1497757920083_0002
2017-06-18 11:58:28,802 INFO org.apache.hadoop.yarn.server.resourcemanager.ClientRMService: Application with id 2 submitted by user root
2017-06-18 11:58:28,808 INFO org.apache.hadoop.yarn.server.resourcemanager.rmapp.RMAppImpl: application_1497757920083_0002 State change from NEW to NEW_SAVING
2017-06-18 11:58:28,809 INFO org.apache.hadoop.yarn.server.resourcemanager.RMAuditLogger: USER=root	IP=192.168.56.178	OPERATION=Submit Application Request	TARGET=ClientRMService	RESULT=SUCCESS	APPID=application_1497757920083_0002
2017-06-18 11:58:28,824 INFO org.apache.hadoop.yarn.server.resourcemanager.recovery.RMStateStore: Storing info for app: application_1497757920083_0002
2017-06-18 11:58:28,827 INFO org.apache.hadoop.yarn.server.resourcemanager.rmapp.RMAppImpl: application_1497757920083_0002 State change from NEW_SAVING to SUBMITTED
2017-06-18 11:58:28,829 INFO org.apache.hadoop.yarn.server.resourcemanager.scheduler.capacity.ParentQueue: Application added - appId: application_1497757920083_0002 user: root leaf-queue of parent: root #applications: 1
2017-06-18 11:58:28,841 INFO org.apache.hadoop.yarn.server.resourcemanager.scheduler.capacity.CapacityScheduler: Accepted application application_1497757920083_0002 from user: root, in queue: default
2017-06-18 11:58:28,873 INFO org.apache.hadoop.yarn.server.resourcemanager.rmapp.RMAppImpl: application_1497757920083_0002 State change from SUBMITTED to ACCEPTED
2017-06-18 11:58:28,939 INFO org.apache.hadoop.yarn.server.resourcemanager.ApplicationMasterService: Registering app attempt : appattempt_1497757920083_0002_000001
2017-06-18 11:58:28,943 INFO org.apache.hadoop.yarn.server.resourcemanager.rmapp.attempt.RMAppAttemptImpl: appattempt_1497757920083_0002_000001 State change from NEW to SUBMITTED
2017-06-18 11:58:28,999 WARN org.apache.hadoop.yarn.server.resourcemanager.scheduler.capacity.LeafQueue: maximum-am-resource-percent is insufficient to start a single application in queue, it is likely set too low. skipping enforcement to allow at least one application to start
2017-06-18 11:58:29,003 WARN org.apache.hadoop.yarn.server.resourcemanager.scheduler.capacity.LeafQueue: maximum-am-resource-percent is insufficient to start a single application in queue for user, it is likely set too low. skipping enforcement to allow at least one application to start
2017-06-18 11:58:29,004 INFO org.apache.hadoop.yarn.server.resourcemanager.scheduler.capacity.LeafQueue: Application application_1497757920083_0002 from user: root activated in queue: default
2017-06-18 11:58:29,004 INFO org.apache.hadoop.yarn.server.resourcemanager.scheduler.capacity.LeafQueue: Application added - appId: application_1497757920083_0002 user: org.apache.hadoop.yarn.server.resourcemanager.scheduler.capacity.LeafQueue$User@5cb4ebf5, leaf-queue: default #user-pending-applications: 0 #user-active-applications: 1 #queue-pending-applications: 0 #queue-active-applications: 1
2017-06-18 11:58:29,004 INFO org.apache.hadoop.yarn.server.resourcemanager.scheduler.capacity.CapacityScheduler: Added Application Attempt appattempt_1497757920083_0002_000001 to scheduler from user root in queue default
2017-06-18 11:58:29,015 INFO org.apache.hadoop.yarn.server.resourcemanager.rmapp.attempt.RMAppAttemptImpl: appattempt_1497757920083_0002_000001 State change from SUBMITTED to SCHEDULED
2017-06-18 11:58:29,883 INFO org.apache.hadoop.yarn.server.resourcemanager.rmcontainer.RMContainerImpl: container_1497757920083_0002_01_000001 Container Transitioned from NEW to ALLOCATED
2017-06-18 11:58:29,883 INFO org.apache.hadoop.yarn.server.resourcemanager.RMAuditLogger: USER=root	OPERATION=AM Allocated Container	TARGET=SchedulerApp	RESULT=SUCCESS	APPID=application_1497757920083_0002	CONTAINERID=container_1497757920083_0002_01_000001
2017-06-18 11:58:29,884 INFO org.apache.hadoop.yarn.server.resourcemanager.scheduler.SchedulerNode: Assigned container container_1497757920083_0002_01_000001 of capacity <memory:2048, vCores:1> on host master:37691, which has 1 containers, <memory:2048, vCores:1> used and <memory:6144, vCores:7> available after allocation
2017-06-18 11:58:29,885 INFO org.apache.hadoop.yarn.server.resourcemanager.scheduler.capacity.LeafQueue: assignedContainer application attempt=appattempt_1497757920083_0002_000001 container=Container: [ContainerId: container_1497757920083_0002_01_000001, NodeId: master:37691, NodeHttpAddress: master:8042, Resource: <memory:2048, vCores:1>, Priority: 0, Token: null, ] queue=default: capacity=1.0, absoluteCapacity=1.0, usedResources=<memory:0, vCores:0>, usedCapacity=0.0, absoluteUsedCapacity=0.0, numApps=1, numContainers=0 clusterResource=<memory:8192, vCores:8>
2017-06-18 11:58:29,891 INFO org.apache.hadoop.yarn.server.resourcemanager.scheduler.capacity.ParentQueue: Re-sorting assigned queue: root.default stats: default: capacity=1.0, absoluteCapacity=1.0, usedResources=<memory:2048, vCores:1>, usedCapacity=0.25, absoluteUsedCapacity=0.25, numApps=1, numContainers=1
2017-06-18 11:58:29,893 INFO org.apache.hadoop.yarn.server.resourcemanager.scheduler.capacity.ParentQueue: assignedContainer queue=root usedCapacity=0.25 absoluteUsedCapacity=0.25 used=<memory:2048, vCores:1> cluster=<memory:8192, vCores:8>
2017-06-18 11:58:29,946 INFO org.apache.hadoop.yarn.server.resourcemanager.security.NMTokenSecretManagerInRM: Sending NMToken for nodeId : master:37691 for container : container_1497757920083_0002_01_000001
2017-06-18 11:58:29,981 INFO org.apache.hadoop.yarn.server.resourcemanager.rmcontainer.RMContainerImpl: container_1497757920083_0002_01_000001 Container Transitioned from ALLOCATED to ACQUIRED
2017-06-18 11:58:29,983 INFO org.apache.hadoop.yarn.server.resourcemanager.security.NMTokenSecretManagerInRM: Clear node set for appattempt_1497757920083_0002_000001
2017-06-18 11:58:29,993 INFO org.apache.hadoop.yarn.server.resourcemanager.rmapp.attempt.RMAppAttemptImpl: Storing attempt: AppId: application_1497757920083_0002 AttemptId: appattempt_1497757920083_0002_000001 MasterContainer: Container: [ContainerId: container_1497757920083_0002_01_000001, NodeId: master:37691, NodeHttpAddress: master:8042, Resource: <memory:2048, vCores:1>, Priority: 0, Token: Token { kind: ContainerToken, service: 192.168.56.178:37691 }, ]
2017-06-18 11:58:30,010 INFO org.apache.hadoop.yarn.server.resourcemanager.rmapp.attempt.RMAppAttemptImpl: appattempt_1497757920083_0002_000001 State change from SCHEDULED to ALLOCATED_SAVING
2017-06-18 11:58:30,032 INFO org.apache.hadoop.yarn.server.resourcemanager.rmapp.attempt.RMAppAttemptImpl: appattempt_1497757920083_0002_000001 State change from ALLOCATED_SAVING to ALLOCATED
2017-06-18 11:58:30,041 INFO org.apache.hadoop.yarn.server.resourcemanager.amlauncher.AMLauncher: Launching masterappattempt_1497757920083_0002_000001
2017-06-18 11:58:30,126 INFO org.apache.hadoop.yarn.server.resourcemanager.amlauncher.AMLauncher: Setting up container Container: [ContainerId: container_1497757920083_0002_01_000001, NodeId: master:37691, NodeHttpAddress: master:8042, Resource: <memory:2048, vCores:1>, Priority: 0, Token: Token { kind: ContainerToken, service: 192.168.56.178:37691 }, ] for AM appattempt_1497757920083_0002_000001
2017-06-18 11:58:30,127 INFO org.apache.hadoop.yarn.server.resourcemanager.amlauncher.AMLauncher: Command to launch container container_1497757920083_0002_01_000001 : $JAVA_HOME/bin/java -Dlog4j.configuration=container-log4j.properties -Dyarn.app.container.log.dir=<LOG_DIR> -Dyarn.app.container.log.filesize=0 -Dhadoop.root.logger=INFO,CLA  -Xmx1024m org.apache.hadoop.mapreduce.v2.app.MRAppMaster 1><LOG_DIR>/stdout 2><LOG_DIR>/stderr 
2017-06-18 11:58:30,131 INFO org.apache.hadoop.yarn.server.resourcemanager.security.AMRMTokenSecretManager: Create AMRMToken for ApplicationAttempt: appattempt_1497757920083_0002_000001
2017-06-18 11:58:30,143 INFO org.apache.hadoop.yarn.server.resourcemanager.security.AMRMTokenSecretManager: Creating password for appattempt_1497757920083_0002_000001
2017-06-18 11:58:31,278 INFO org.apache.hadoop.yarn.server.resourcemanager.amlauncher.AMLauncher: Done launching container Container: [ContainerId: container_1497757920083_0002_01_000001, NodeId: master:37691, NodeHttpAddress: master:8042, Resource: <memory:2048, vCores:1>, Priority: 0, Token: Token { kind: ContainerToken, service: 192.168.56.178:37691 }, ] for AM appattempt_1497757920083_0002_000001
2017-06-18 11:58:31,279 INFO org.apache.hadoop.yarn.server.resourcemanager.rmapp.attempt.RMAppAttemptImpl: appattempt_1497757920083_0002_000001 State change from ALLOCATED to LAUNCHED
2017-06-18 11:58:31,909 INFO org.apache.hadoop.yarn.server.resourcemanager.rmcontainer.RMContainerImpl: container_1497757920083_0002_01_000001 Container Transitioned from ACQUIRED to RUNNING
2017-06-18 11:58:47,660 INFO SecurityLogger.org.apache.hadoop.ipc.Server: Auth successful for appattempt_1497757920083_0002_000001 (auth:SIMPLE)
2017-06-18 11:58:47,688 INFO org.apache.hadoop.yarn.server.resourcemanager.ApplicationMasterService: AM registration appattempt_1497757920083_0002_000001
2017-06-18 11:58:47,692 INFO org.apache.hadoop.yarn.server.resourcemanager.rmapp.attempt.RMAppAttemptImpl: appattempt_1497757920083_0002_000001 State change from LAUNCHED to RUNNING
2017-06-18 11:58:47,692 INFO org.apache.hadoop.yarn.server.resourcemanager.rmapp.RMAppImpl: application_1497757920083_0002 State change from ACCEPTED to RUNNING
2017-06-18 11:58:47,692 INFO org.apache.hadoop.yarn.server.resourcemanager.RMAuditLogger: USER=root	IP=192.168.56.178	OPERATION=Register App Master	TARGET=ApplicationMasterService	RESULT=SUCCESS	APPID=application_1497757920083_0002	APPATTEMPTID=appattempt_1497757920083_0002_000001
2017-06-18 11:58:50,992 INFO org.apache.hadoop.yarn.server.resourcemanager.rmcontainer.RMContainerImpl: container_1497757920083_0002_01_000002 Container Transitioned from NEW to ALLOCATED
2017-06-18 11:58:50,993 INFO org.apache.hadoop.yarn.server.resourcemanager.RMAuditLogger: USER=root	OPERATION=AM Allocated Container	TARGET=SchedulerApp	RESULT=SUCCESS	APPID=application_1497757920083_0002	CONTAINERID=container_1497757920083_0002_01_000002
2017-06-18 11:58:50,993 INFO org.apache.hadoop.yarn.server.resourcemanager.scheduler.SchedulerNode: Assigned container container_1497757920083_0002_01_000002 of capacity <memory:1024, vCores:1> on host master:37691, which has 2 containers, <memory:3072, vCores:2> used and <memory:5120, vCores:6> available after allocation
2017-06-18 11:58:50,993 INFO org.apache.hadoop.yarn.server.resourcemanager.scheduler.capacity.LeafQueue: assignedContainer application attempt=appattempt_1497757920083_0002_000001 container=Container: [ContainerId: container_1497757920083_0002_01_000002, NodeId: master:37691, NodeHttpAddress: master:8042, Resource: <memory:1024, vCores:1>, Priority: 10, Token: null, ] queue=default: capacity=1.0, absoluteCapacity=1.0, usedResources=<memory:2048, vCores:1>, usedCapacity=0.25, absoluteUsedCapacity=0.25, numApps=1, numContainers=1 clusterResource=<memory:8192, vCores:8>
2017-06-18 11:58:50,993 INFO org.apache.hadoop.yarn.server.resourcemanager.scheduler.capacity.ParentQueue: Re-sorting assigned queue: root.default stats: default: capacity=1.0, absoluteCapacity=1.0, usedResources=<memory:3072, vCores:2>, usedCapacity=0.375, absoluteUsedCapacity=0.375, numApps=1, numContainers=2
2017-06-18 11:58:50,994 INFO org.apache.hadoop.yarn.server.resourcemanager.scheduler.capacity.ParentQueue: assignedContainer queue=root usedCapacity=0.375 absoluteUsedCapacity=0.375 used=<memory:3072, vCores:2> cluster=<memory:8192, vCores:8>
2017-06-18 11:58:51,182 INFO org.apache.hadoop.yarn.server.resourcemanager.security.NMTokenSecretManagerInRM: Sending NMToken for nodeId : master:37691 for container : container_1497757920083_0002_01_000002
2017-06-18 11:58:51,192 INFO org.apache.hadoop.yarn.server.resourcemanager.rmcontainer.RMContainerImpl: container_1497757920083_0002_01_000002 Container Transitioned from ALLOCATED to ACQUIRED
2017-06-18 11:58:51,997 INFO org.apache.hadoop.yarn.server.resourcemanager.rmcontainer.RMContainerImpl: container_1497757920083_0002_01_000002 Container Transitioned from ACQUIRED to RUNNING
2017-06-18 11:58:52,233 INFO org.apache.hadoop.yarn.server.resourcemanager.scheduler.AppSchedulingInfo: checking for deactivate... 
2017-06-18 11:59:00,857 INFO org.apache.hadoop.yarn.server.resourcemanager.rmcontainer.RMContainerImpl: container_1497757920083_0002_01_000002 Container Transitioned from RUNNING to COMPLETED
2017-06-18 11:59:00,857 INFO org.apache.hadoop.yarn.server.resourcemanager.scheduler.common.fica.FiCaSchedulerApp: Completed container: container_1497757920083_0002_01_000002 in state: COMPLETED event:FINISHED
2017-06-18 11:59:00,865 INFO org.apache.hadoop.yarn.server.resourcemanager.RMAuditLogger: USER=root	OPERATION=AM Released Container	TARGET=SchedulerApp	RESULT=SUCCESS	APPID=application_1497757920083_0002	CONTAINERID=container_1497757920083_0002_01_000002
2017-06-18 11:59:00,866 INFO org.apache.hadoop.yarn.server.resourcemanager.scheduler.SchedulerNode: Released container container_1497757920083_0002_01_000002 of capacity <memory:1024, vCores:1> on host master:37691, which currently has 1 containers, <memory:2048, vCores:1> used and <memory:6144, vCores:7> available, release resources=true
2017-06-18 11:59:00,866 INFO org.apache.hadoop.yarn.server.resourcemanager.scheduler.capacity.LeafQueue: default used=<memory:2048, vCores:1> numContainers=1 user=root user-resources=<memory:2048, vCores:1>
2017-06-18 11:59:00,867 INFO org.apache.hadoop.yarn.server.resourcemanager.scheduler.capacity.LeafQueue: completedContainer container=Container: [ContainerId: container_1497757920083_0002_01_000002, NodeId: master:37691, NodeHttpAddress: master:8042, Resource: <memory:1024, vCores:1>, Priority: 10, Token: Token { kind: ContainerToken, service: 192.168.56.178:37691 }, ] queue=default: capacity=1.0, absoluteCapacity=1.0, usedResources=<memory:2048, vCores:1>, usedCapacity=0.25, absoluteUsedCapacity=0.25, numApps=1, numContainers=1 cluster=<memory:8192, vCores:8>
2017-06-18 11:59:00,867 INFO org.apache.hadoop.yarn.server.resourcemanager.scheduler.capacity.ParentQueue: completedContainer queue=root usedCapacity=0.25 absoluteUsedCapacity=0.25 used=<memory:2048, vCores:1> cluster=<memory:8192, vCores:8>
2017-06-18 11:59:00,867 INFO org.apache.hadoop.yarn.server.resourcemanager.scheduler.capacity.ParentQueue: Re-sorting completed queue: root.default stats: default: capacity=1.0, absoluteCapacity=1.0, usedResources=<memory:2048, vCores:1>, usedCapacity=0.25, absoluteUsedCapacity=0.25, numApps=1, numContainers=1
2017-06-18 11:59:00,867 INFO org.apache.hadoop.yarn.server.resourcemanager.scheduler.capacity.CapacityScheduler: Application attempt appattempt_1497757920083_0002_000001 released container container_1497757920083_0002_01_000002 on node: host: master:37691 #containers=1 available=6144 used=2048 with event: FINISHED
2017-06-18 11:59:01,462 INFO org.apache.hadoop.yarn.server.resourcemanager.rmapp.attempt.RMAppAttemptImpl: Updating application attempt appattempt_1497757920083_0002_000001 with final state: FINISHING, and exit status: -1000
2017-06-18 11:59:01,476 INFO org.apache.hadoop.yarn.server.resourcemanager.rmapp.attempt.RMAppAttemptImpl: appattempt_1497757920083_0002_000001 State change from RUNNING to FINAL_SAVING
2017-06-18 11:59:01,479 INFO org.apache.hadoop.yarn.server.resourcemanager.rmapp.RMAppImpl: Updating application application_1497757920083_0002 with final state: FINISHING
2017-06-18 11:59:01,480 INFO org.apache.hadoop.yarn.server.resourcemanager.recovery.RMStateStore: Updating info for app: application_1497757920083_0002
2017-06-18 11:59:01,480 INFO org.apache.hadoop.yarn.server.resourcemanager.rmapp.RMAppImpl: application_1497757920083_0002 State change from RUNNING to FINAL_SAVING
2017-06-18 11:59:01,481 INFO org.apache.hadoop.yarn.server.resourcemanager.rmapp.attempt.RMAppAttemptImpl: appattempt_1497757920083_0002_000001 State change from FINAL_SAVING to FINISHING
2017-06-18 11:59:01,482 INFO org.apache.hadoop.yarn.server.resourcemanager.rmapp.RMAppImpl: application_1497757920083_0002 State change from FINAL_SAVING to FINISHING
2017-06-18 11:59:02,501 INFO org.apache.hadoop.yarn.server.resourcemanager.ApplicationMasterService: application_1497757920083_0002 unregistered successfully. 
2017-06-18 11:59:04,105 INFO org.apache.hadoop.yarn.server.resourcemanager.ClientRMService: Allocated new applicationId: 3
2017-06-18 11:59:04,507 INFO org.apache.hadoop.yarn.server.resourcemanager.ClientRMService: Application with id 3 submitted by user root
2017-06-18 11:59:04,507 INFO org.apache.hadoop.yarn.server.resourcemanager.rmapp.RMAppImpl: Storing application with id application_1497757920083_0003
2017-06-18 11:59:04,507 INFO org.apache.hadoop.yarn.server.resourcemanager.rmapp.RMAppImpl: application_1497757920083_0003 State change from NEW to NEW_SAVING
2017-06-18 11:59:04,507 INFO org.apache.hadoop.yarn.server.resourcemanager.recovery.RMStateStore: Storing info for app: application_1497757920083_0003
2017-06-18 11:59:04,509 INFO org.apache.hadoop.yarn.server.resourcemanager.rmapp.RMAppImpl: application_1497757920083_0003 State change from NEW_SAVING to SUBMITTED
2017-06-18 11:59:04,509 INFO org.apache.hadoop.yarn.server.resourcemanager.scheduler.capacity.ParentQueue: Application added - appId: application_1497757920083_0003 user: root leaf-queue of parent: root #applications: 2
2017-06-18 11:59:04,509 INFO org.apache.hadoop.yarn.server.resourcemanager.scheduler.capacity.CapacityScheduler: Accepted application application_1497757920083_0003 from user: root, in queue: default
2017-06-18 11:59:04,510 INFO org.apache.hadoop.yarn.server.resourcemanager.rmapp.RMAppImpl: application_1497757920083_0003 State change from SUBMITTED to ACCEPTED
2017-06-18 11:59:04,510 INFO org.apache.hadoop.yarn.server.resourcemanager.ApplicationMasterService: Registering app attempt : appattempt_1497757920083_0003_000001
2017-06-18 11:59:04,510 INFO org.apache.hadoop.yarn.server.resourcemanager.rmapp.attempt.RMAppAttemptImpl: appattempt_1497757920083_0003_000001 State change from NEW to SUBMITTED
2017-06-18 11:59:04,510 INFO org.apache.hadoop.yarn.server.resourcemanager.scheduler.capacity.LeafQueue: not starting application as amIfStarted exceeds amLimit
2017-06-18 11:59:04,510 INFO org.apache.hadoop.yarn.server.resourcemanager.scheduler.capacity.LeafQueue: Application added - appId: application_1497757920083_0003 user: org.apache.hadoop.yarn.server.resourcemanager.scheduler.capacity.LeafQueue$User@5cb4ebf5, leaf-queue: default #user-pending-applications: 1 #user-active-applications: 1 #queue-pending-applications: 1 #queue-active-applications: 1
2017-06-18 11:59:04,510 INFO org.apache.hadoop.yarn.server.resourcemanager.scheduler.capacity.CapacityScheduler: Added Application Attempt appattempt_1497757920083_0003_000001 to scheduler from user root in queue default
2017-06-18 11:59:04,511 INFO org.apache.hadoop.yarn.server.resourcemanager.RMAuditLogger: USER=root	IP=192.168.56.178	OPERATION=Submit Application Request	TARGET=ClientRMService	RESULT=SUCCESS	APPID=application_1497757920083_0003
2017-06-18 11:59:04,513 INFO org.apache.hadoop.yarn.server.resourcemanager.rmapp.attempt.RMAppAttemptImpl: appattempt_1497757920083_0003_000001 State change from SUBMITTED to SCHEDULED
2017-06-18 11:59:07,703 INFO org.apache.hadoop.yarn.server.resourcemanager.rmcontainer.RMContainerImpl: container_1497757920083_0002_01_000001 Container Transitioned from RUNNING to COMPLETED
2017-06-18 11:59:07,703 INFO org.apache.hadoop.yarn.server.resourcemanager.scheduler.common.fica.FiCaSchedulerApp: Completed container: container_1497757920083_0002_01_000001 in state: COMPLETED event:FINISHED
2017-06-18 11:59:07,703 INFO org.apache.hadoop.yarn.server.resourcemanager.RMAuditLogger: USER=root	OPERATION=AM Released Container	TARGET=SchedulerApp	RESULT=SUCCESS	APPID=application_1497757920083_0002	CONTAINERID=container_1497757920083_0002_01_000001
2017-06-18 11:59:07,703 INFO org.apache.hadoop.yarn.server.resourcemanager.scheduler.SchedulerNode: Released container container_1497757920083_0002_01_000001 of capacity <memory:2048, vCores:1> on host master:37691, which currently has 0 containers, <memory:0, vCores:0> used and <memory:8192, vCores:8> available, release resources=true
2017-06-18 11:59:07,703 INFO org.apache.hadoop.yarn.server.resourcemanager.scheduler.capacity.LeafQueue: default used=<memory:0, vCores:0> numContainers=0 user=root user-resources=<memory:0, vCores:0>
2017-06-18 11:59:07,703 INFO org.apache.hadoop.yarn.server.resourcemanager.scheduler.capacity.LeafQueue: completedContainer container=Container: [ContainerId: container_1497757920083_0002_01_000001, NodeId: master:37691, NodeHttpAddress: master:8042, Resource: <memory:2048, vCores:1>, Priority: 0, Token: Token { kind: ContainerToken, service: 192.168.56.178:37691 }, ] queue=default: capacity=1.0, absoluteCapacity=1.0, usedResources=<memory:0, vCores:0>, usedCapacity=0.0, absoluteUsedCapacity=0.0, numApps=2, numContainers=0 cluster=<memory:8192, vCores:8>
2017-06-18 11:59:07,703 INFO org.apache.hadoop.yarn.server.resourcemanager.scheduler.capacity.ParentQueue: completedContainer queue=root usedCapacity=0.0 absoluteUsedCapacity=0.0 used=<memory:0, vCores:0> cluster=<memory:8192, vCores:8>
2017-06-18 11:59:07,703 INFO org.apache.hadoop.yarn.server.resourcemanager.scheduler.capacity.ParentQueue: Re-sorting completed queue: root.default stats: default: capacity=1.0, absoluteCapacity=1.0, usedResources=<memory:0, vCores:0>, usedCapacity=0.0, absoluteUsedCapacity=0.0, numApps=2, numContainers=0
2017-06-18 11:59:07,704 INFO org.apache.hadoop.yarn.server.resourcemanager.scheduler.capacity.CapacityScheduler: Application attempt appattempt_1497757920083_0002_000001 released container container_1497757920083_0002_01_000001 on node: host: master:37691 #containers=0 available=8192 used=0 with event: FINISHED
2017-06-18 11:59:07,705 INFO org.apache.hadoop.yarn.server.resourcemanager.ApplicationMasterService: Unregistering app attempt : appattempt_1497757920083_0002_000001
2017-06-18 11:59:07,707 INFO org.apache.hadoop.yarn.server.resourcemanager.security.AMRMTokenSecretManager: Application finished, removing password for appattempt_1497757920083_0002_000001
2017-06-18 11:59:07,710 INFO org.apache.hadoop.yarn.server.resourcemanager.rmapp.attempt.RMAppAttemptImpl: appattempt_1497757920083_0002_000001 State change from FINISHING to FINISHED
2017-06-18 11:59:07,713 INFO org.apache.hadoop.yarn.server.resourcemanager.rmapp.RMAppImpl: application_1497757920083_0002 State change from FINISHING to FINISHED
2017-06-18 11:59:07,716 INFO org.apache.hadoop.yarn.server.resourcemanager.scheduler.capacity.CapacityScheduler: Application Attempt appattempt_1497757920083_0002_000001 is done. finalState=FINISHED
2017-06-18 11:59:07,717 INFO org.apache.hadoop.yarn.server.resourcemanager.scheduler.AppSchedulingInfo: Application application_1497757920083_0002 requests cleared
2017-06-18 11:59:07,718 WARN org.apache.hadoop.yarn.server.resourcemanager.scheduler.capacity.LeafQueue: maximum-am-resource-percent is insufficient to start a single application in queue, it is likely set too low. skipping enforcement to allow at least one application to start
2017-06-18 11:59:07,718 WARN org.apache.hadoop.yarn.server.resourcemanager.scheduler.capacity.LeafQueue: maximum-am-resource-percent is insufficient to start a single application in queue for user, it is likely set too low. skipping enforcement to allow at least one application to start
2017-06-18 11:59:07,718 INFO org.apache.hadoop.yarn.server.resourcemanager.scheduler.capacity.LeafQueue: Application application_1497757920083_0003 from user: root activated in queue: default
2017-06-18 11:59:07,718 INFO org.apache.hadoop.yarn.server.resourcemanager.scheduler.capacity.LeafQueue: Application removed - appId: application_1497757920083_0002 user: root queue: default #user-pending-applications: 0 #user-active-applications: 1 #queue-pending-applications: 0 #queue-active-applications: 1
2017-06-18 11:59:07,718 INFO org.apache.hadoop.yarn.server.resourcemanager.scheduler.capacity.ParentQueue: Application removed - appId: application_1497757920083_0002 user: root leaf-queue of parent: root #applications: 1
2017-06-18 11:59:07,720 INFO org.apache.hadoop.yarn.server.resourcemanager.RMAuditLogger: USER=root	OPERATION=Application Finished - Succeeded	TARGET=RMAppManager	RESULT=SUCCESS	APPID=application_1497757920083_0002
2017-06-18 11:59:07,721 INFO org.apache.hadoop.yarn.server.resourcemanager.amlauncher.AMLauncher: Cleaning master appattempt_1497757920083_0002_000001
2017-06-18 11:59:07,739 INFO org.apache.hadoop.yarn.server.resourcemanager.RMAppManager$ApplicationSummary: appId=application_1497757920083_0002,name=grep-search,user=root,queue=default,state=FINISHED,trackingUrl=http://master:8088/proxy/application_1497757920083_0002/,appMasterHost=master,startTime=1497758308795,finishTime=1497758341478,finalStatus=SUCCEEDED
2017-06-18 11:59:08,711 INFO org.apache.hadoop.yarn.server.resourcemanager.rmcontainer.RMContainerImpl: container_1497757920083_0003_01_000001 Container Transitioned from NEW to ALLOCATED
2017-06-18 11:59:08,711 INFO org.apache.hadoop.yarn.server.resourcemanager.RMAuditLogger: USER=root	OPERATION=AM Allocated Container	TARGET=SchedulerApp	RESULT=SUCCESS	APPID=application_1497757920083_0003	CONTAINERID=container_1497757920083_0003_01_000001
2017-06-18 11:59:08,711 INFO org.apache.hadoop.yarn.server.resourcemanager.scheduler.SchedulerNode: Assigned container container_1497757920083_0003_01_000001 of capacity <memory:2048, vCores:1> on host master:37691, which has 1 containers, <memory:2048, vCores:1> used and <memory:6144, vCores:7> available after allocation
2017-06-18 11:59:08,711 INFO org.apache.hadoop.yarn.server.resourcemanager.scheduler.capacity.LeafQueue: assignedContainer application attempt=appattempt_1497757920083_0003_000001 container=Container: [ContainerId: container_1497757920083_0003_01_000001, NodeId: master:37691, NodeHttpAddress: master:8042, Resource: <memory:2048, vCores:1>, Priority: 0, Token: null, ] queue=default: capacity=1.0, absoluteCapacity=1.0, usedResources=<memory:0, vCores:0>, usedCapacity=0.0, absoluteUsedCapacity=0.0, numApps=1, numContainers=0 clusterResource=<memory:8192, vCores:8>
2017-06-18 11:59:08,712 INFO org.apache.hadoop.yarn.server.resourcemanager.scheduler.capacity.ParentQueue: Re-sorting assigned queue: root.default stats: default: capacity=1.0, absoluteCapacity=1.0, usedResources=<memory:2048, vCores:1>, usedCapacity=0.25, absoluteUsedCapacity=0.25, numApps=1, numContainers=1
2017-06-18 11:59:08,712 INFO org.apache.hadoop.yarn.server.resourcemanager.scheduler.capacity.ParentQueue: assignedContainer queue=root usedCapacity=0.25 absoluteUsedCapacity=0.25 used=<memory:2048, vCores:1> cluster=<memory:8192, vCores:8>
2017-06-18 11:59:08,713 INFO org.apache.hadoop.yarn.server.resourcemanager.security.NMTokenSecretManagerInRM: Sending NMToken for nodeId : master:37691 for container : container_1497757920083_0003_01_000001
2017-06-18 11:59:08,746 INFO org.apache.hadoop.yarn.server.resourcemanager.rmcontainer.RMContainerImpl: container_1497757920083_0003_01_000001 Container Transitioned from ALLOCATED to ACQUIRED
2017-06-18 11:59:08,747 INFO org.apache.hadoop.yarn.server.resourcemanager.security.NMTokenSecretManagerInRM: Clear node set for appattempt_1497757920083_0003_000001
2017-06-18 11:59:08,747 INFO org.apache.hadoop.yarn.server.resourcemanager.rmapp.attempt.RMAppAttemptImpl: Storing attempt: AppId: application_1497757920083_0003 AttemptId: appattempt_1497757920083_0003_000001 MasterContainer: Container: [ContainerId: container_1497757920083_0003_01_000001, NodeId: master:37691, NodeHttpAddress: master:8042, Resource: <memory:2048, vCores:1>, Priority: 0, Token: Token { kind: ContainerToken, service: 192.168.56.178:37691 }, ]
2017-06-18 11:59:08,749 INFO org.apache.hadoop.yarn.server.resourcemanager.rmapp.attempt.RMAppAttemptImpl: appattempt_1497757920083_0003_000001 State change from SCHEDULED to ALLOCATED_SAVING
2017-06-18 11:59:08,749 INFO org.apache.hadoop.yarn.server.resourcemanager.rmapp.attempt.RMAppAttemptImpl: appattempt_1497757920083_0003_000001 State change from ALLOCATED_SAVING to ALLOCATED
2017-06-18 11:59:08,757 INFO org.apache.hadoop.yarn.server.resourcemanager.amlauncher.AMLauncher: Launching masterappattempt_1497757920083_0003_000001
2017-06-18 11:59:08,768 INFO org.apache.hadoop.yarn.server.resourcemanager.amlauncher.AMLauncher: Setting up container Container: [ContainerId: container_1497757920083_0003_01_000001, NodeId: master:37691, NodeHttpAddress: master:8042, Resource: <memory:2048, vCores:1>, Priority: 0, Token: Token { kind: ContainerToken, service: 192.168.56.178:37691 }, ] for AM appattempt_1497757920083_0003_000001
2017-06-18 11:59:08,769 INFO org.apache.hadoop.yarn.server.resourcemanager.amlauncher.AMLauncher: Command to launch container container_1497757920083_0003_01_000001 : $JAVA_HOME/bin/java -Dlog4j.configuration=container-log4j.properties -Dyarn.app.container.log.dir=<LOG_DIR> -Dyarn.app.container.log.filesize=0 -Dhadoop.root.logger=INFO,CLA  -Xmx1024m org.apache.hadoop.mapreduce.v2.app.MRAppMaster 1><LOG_DIR>/stdout 2><LOG_DIR>/stderr 
2017-06-18 11:59:08,770 INFO org.apache.hadoop.yarn.server.resourcemanager.security.AMRMTokenSecretManager: Create AMRMToken for ApplicationAttempt: appattempt_1497757920083_0003_000001
2017-06-18 11:59:08,770 INFO org.apache.hadoop.yarn.server.resourcemanager.security.AMRMTokenSecretManager: Creating password for appattempt_1497757920083_0003_000001
2017-06-18 11:59:08,821 INFO org.apache.hadoop.yarn.server.resourcemanager.amlauncher.AMLauncher: Done launching container Container: [ContainerId: container_1497757920083_0003_01_000001, NodeId: master:37691, NodeHttpAddress: master:8042, Resource: <memory:2048, vCores:1>, Priority: 0, Token: Token { kind: ContainerToken, service: 192.168.56.178:37691 }, ] for AM appattempt_1497757920083_0003_000001
2017-06-18 11:59:08,821 INFO org.apache.hadoop.yarn.server.resourcemanager.rmapp.attempt.RMAppAttemptImpl: appattempt_1497757920083_0003_000001 State change from ALLOCATED to LAUNCHED
2017-06-18 11:59:09,735 INFO org.apache.hadoop.yarn.server.resourcemanager.rmcontainer.RMContainerImpl: container_1497757920083_0003_01_000001 Container Transitioned from ACQUIRED to RUNNING
2017-06-18 11:59:22,207 INFO SecurityLogger.org.apache.hadoop.ipc.Server: Auth successful for appattempt_1497757920083_0003_000001 (auth:SIMPLE)
2017-06-18 11:59:22,224 INFO org.apache.hadoop.yarn.server.resourcemanager.ApplicationMasterService: AM registration appattempt_1497757920083_0003_000001
2017-06-18 11:59:22,225 INFO org.apache.hadoop.yarn.server.resourcemanager.rmapp.attempt.RMAppAttemptImpl: appattempt_1497757920083_0003_000001 State change from LAUNCHED to RUNNING
2017-06-18 11:59:22,225 INFO org.apache.hadoop.yarn.server.resourcemanager.rmapp.RMAppImpl: application_1497757920083_0003 State change from ACCEPTED to RUNNING
2017-06-18 11:59:22,226 INFO org.apache.hadoop.yarn.server.resourcemanager.RMAuditLogger: USER=root	IP=192.168.56.178	OPERATION=Register App Master	TARGET=ApplicationMasterService	RESULT=SUCCESS	APPID=application_1497757920083_0003	APPATTEMPTID=appattempt_1497757920083_0003_000001
2017-06-18 11:59:23,780 INFO org.apache.hadoop.yarn.server.resourcemanager.rmcontainer.RMContainerImpl: container_1497757920083_0003_01_000002 Container Transitioned from NEW to ALLOCATED
2017-06-18 11:59:23,780 INFO org.apache.hadoop.yarn.server.resourcemanager.RMAuditLogger: USER=root	OPERATION=AM Allocated Container	TARGET=SchedulerApp	RESULT=SUCCESS	APPID=application_1497757920083_0003	CONTAINERID=container_1497757920083_0003_01_000002
2017-06-18 11:59:23,781 INFO org.apache.hadoop.yarn.server.resourcemanager.scheduler.SchedulerNode: Assigned container container_1497757920083_0003_01_000002 of capacity <memory:1024, vCores:1> on host master:37691, which has 2 containers, <memory:3072, vCores:2> used and <memory:5120, vCores:6> available after allocation
2017-06-18 11:59:23,781 INFO org.apache.hadoop.yarn.server.resourcemanager.scheduler.capacity.LeafQueue: assignedContainer application attempt=appattempt_1497757920083_0003_000001 container=Container: [ContainerId: container_1497757920083_0003_01_000002, NodeId: master:37691, NodeHttpAddress: master:8042, Resource: <memory:1024, vCores:1>, Priority: 20, Token: null, ] queue=default: capacity=1.0, absoluteCapacity=1.0, usedResources=<memory:2048, vCores:1>, usedCapacity=0.25, absoluteUsedCapacity=0.25, numApps=1, numContainers=1 clusterResource=<memory:8192, vCores:8>
2017-06-18 11:59:23,783 INFO org.apache.hadoop.yarn.server.resourcemanager.scheduler.capacity.ParentQueue: Re-sorting assigned queue: root.default stats: default: capacity=1.0, absoluteCapacity=1.0, usedResources=<memory:3072, vCores:2>, usedCapacity=0.375, absoluteUsedCapacity=0.375, numApps=1, numContainers=2
2017-06-18 11:59:23,783 INFO org.apache.hadoop.yarn.server.resourcemanager.scheduler.capacity.ParentQueue: assignedContainer queue=root usedCapacity=0.375 absoluteUsedCapacity=0.375 used=<memory:3072, vCores:2> cluster=<memory:8192, vCores:8>
2017-06-18 11:59:24,517 INFO org.apache.hadoop.yarn.server.resourcemanager.security.NMTokenSecretManagerInRM: Sending NMToken for nodeId : master:37691 for container : container_1497757920083_0003_01_000002
2017-06-18 11:59:24,522 INFO org.apache.hadoop.yarn.server.resourcemanager.rmcontainer.RMContainerImpl: container_1497757920083_0003_01_000002 Container Transitioned from ALLOCATED to ACQUIRED
2017-06-18 11:59:25,585 INFO org.apache.hadoop.yarn.server.resourcemanager.scheduler.AppSchedulingInfo: checking for deactivate... 
2017-06-18 11:59:25,789 INFO org.apache.hadoop.yarn.server.resourcemanager.rmcontainer.RMContainerImpl: container_1497757920083_0003_01_000002 Container Transitioned from ACQUIRED to RUNNING
2017-06-18 11:59:33,837 INFO org.apache.hadoop.yarn.server.resourcemanager.rmcontainer.RMContainerImpl: container_1497757920083_0003_01_000002 Container Transitioned from RUNNING to COMPLETED
2017-06-18 11:59:33,837 INFO org.apache.hadoop.yarn.server.resourcemanager.scheduler.common.fica.FiCaSchedulerApp: Completed container: container_1497757920083_0003_01_000002 in state: COMPLETED event:FINISHED
2017-06-18 11:59:33,837 INFO org.apache.hadoop.yarn.server.resourcemanager.RMAuditLogger: USER=root	OPERATION=AM Released Container	TARGET=SchedulerApp	RESULT=SUCCESS	APPID=application_1497757920083_0003	CONTAINERID=container_1497757920083_0003_01_000002
2017-06-18 11:59:33,837 INFO org.apache.hadoop.yarn.server.resourcemanager.scheduler.SchedulerNode: Released container container_1497757920083_0003_01_000002 of capacity <memory:1024, vCores:1> on host master:37691, which currently has 1 containers, <memory:2048, vCores:1> used and <memory:6144, vCores:7> available, release resources=true
2017-06-18 11:59:33,837 INFO org.apache.hadoop.yarn.server.resourcemanager.scheduler.capacity.LeafQueue: default used=<memory:2048, vCores:1> numContainers=1 user=root user-resources=<memory:2048, vCores:1>
2017-06-18 11:59:33,839 INFO org.apache.hadoop.yarn.server.resourcemanager.scheduler.capacity.LeafQueue: completedContainer container=Container: [ContainerId: container_1497757920083_0003_01_000002, NodeId: master:37691, NodeHttpAddress: master:8042, Resource: <memory:1024, vCores:1>, Priority: 20, Token: Token { kind: ContainerToken, service: 192.168.56.178:37691 }, ] queue=default: capacity=1.0, absoluteCapacity=1.0, usedResources=<memory:2048, vCores:1>, usedCapacity=0.25, absoluteUsedCapacity=0.25, numApps=1, numContainers=1 cluster=<memory:8192, vCores:8>
2017-06-18 11:59:33,840 INFO org.apache.hadoop.yarn.server.resourcemanager.scheduler.capacity.ParentQueue: completedContainer queue=root usedCapacity=0.25 absoluteUsedCapacity=0.25 used=<memory:2048, vCores:1> cluster=<memory:8192, vCores:8>
2017-06-18 11:59:33,840 INFO org.apache.hadoop.yarn.server.resourcemanager.scheduler.capacity.ParentQueue: Re-sorting completed queue: root.default stats: default: capacity=1.0, absoluteCapacity=1.0, usedResources=<memory:2048, vCores:1>, usedCapacity=0.25, absoluteUsedCapacity=0.25, numApps=1, numContainers=1
2017-06-18 11:59:33,840 INFO org.apache.hadoop.yarn.server.resourcemanager.scheduler.capacity.CapacityScheduler: Application attempt appattempt_1497757920083_0003_000001 released container container_1497757920083_0003_01_000002 on node: host: master:37691 #containers=1 available=6144 used=2048 with event: FINISHED
2017-06-18 11:59:35,844 INFO org.apache.hadoop.yarn.server.resourcemanager.rmcontainer.RMContainerImpl: container_1497757920083_0003_01_000003 Container Transitioned from NEW to ALLOCATED
2017-06-18 11:59:35,844 INFO org.apache.hadoop.yarn.server.resourcemanager.RMAuditLogger: USER=root	OPERATION=AM Allocated Container	TARGET=SchedulerApp	RESULT=SUCCESS	APPID=application_1497757920083_0003	CONTAINERID=container_1497757920083_0003_01_000003
2017-06-18 11:59:35,844 INFO org.apache.hadoop.yarn.server.resourcemanager.scheduler.SchedulerNode: Assigned container container_1497757920083_0003_01_000003 of capacity <memory:1024, vCores:1> on host master:37691, which has 2 containers, <memory:3072, vCores:2> used and <memory:5120, vCores:6> available after allocation
2017-06-18 11:59:35,844 INFO org.apache.hadoop.yarn.server.resourcemanager.scheduler.capacity.LeafQueue: assignedContainer application attempt=appattempt_1497757920083_0003_000001 container=Container: [ContainerId: container_1497757920083_0003_01_000003, NodeId: master:37691, NodeHttpAddress: master:8042, Resource: <memory:1024, vCores:1>, Priority: 10, Token: null, ] queue=default: capacity=1.0, absoluteCapacity=1.0, usedResources=<memory:2048, vCores:1>, usedCapacity=0.25, absoluteUsedCapacity=0.25, numApps=1, numContainers=1 clusterResource=<memory:8192, vCores:8>
2017-06-18 11:59:35,844 INFO org.apache.hadoop.yarn.server.resourcemanager.scheduler.capacity.ParentQueue: Re-sorting assigned queue: root.default stats: default: capacity=1.0, absoluteCapacity=1.0, usedResources=<memory:3072, vCores:2>, usedCapacity=0.375, absoluteUsedCapacity=0.375, numApps=1, numContainers=2
2017-06-18 11:59:35,845 INFO org.apache.hadoop.yarn.server.resourcemanager.scheduler.capacity.ParentQueue: assignedContainer queue=root usedCapacity=0.375 absoluteUsedCapacity=0.375 used=<memory:3072, vCores:2> cluster=<memory:8192, vCores:8>
2017-06-18 11:59:36,646 INFO org.apache.hadoop.yarn.server.resourcemanager.rmcontainer.RMContainerImpl: container_1497757920083_0003_01_000003 Container Transitioned from ALLOCATED to ACQUIRED
2017-06-18 11:59:36,854 INFO org.apache.hadoop.yarn.server.resourcemanager.rmcontainer.RMContainerImpl: container_1497757920083_0003_01_000003 Container Transitioned from ACQUIRED to RUNNING
2017-06-18 11:59:37,655 INFO org.apache.hadoop.yarn.server.resourcemanager.scheduler.AppSchedulingInfo: checking for deactivate... 
2017-06-18 11:59:45,509 INFO org.apache.hadoop.yarn.server.resourcemanager.rmcontainer.RMContainerImpl: container_1497757920083_0003_01_000003 Container Transitioned from RUNNING to COMPLETED
2017-06-18 11:59:45,509 INFO org.apache.hadoop.yarn.server.resourcemanager.scheduler.common.fica.FiCaSchedulerApp: Completed container: container_1497757920083_0003_01_000003 in state: COMPLETED event:FINISHED
2017-06-18 11:59:45,509 INFO org.apache.hadoop.yarn.server.resourcemanager.RMAuditLogger: USER=root	OPERATION=AM Released Container	TARGET=SchedulerApp	RESULT=SUCCESS	APPID=application_1497757920083_0003	CONTAINERID=container_1497757920083_0003_01_000003
2017-06-18 11:59:45,509 INFO org.apache.hadoop.yarn.server.resourcemanager.scheduler.SchedulerNode: Released container container_1497757920083_0003_01_000003 of capacity <memory:1024, vCores:1> on host master:37691, which currently has 1 containers, <memory:2048, vCores:1> used and <memory:6144, vCores:7> available, release resources=true
2017-06-18 11:59:45,509 INFO org.apache.hadoop.yarn.server.resourcemanager.scheduler.capacity.LeafQueue: default used=<memory:2048, vCores:1> numContainers=1 user=root user-resources=<memory:2048, vCores:1>
2017-06-18 11:59:45,512 INFO org.apache.hadoop.yarn.server.resourcemanager.scheduler.capacity.LeafQueue: completedContainer container=Container: [ContainerId: container_1497757920083_0003_01_000003, NodeId: master:37691, NodeHttpAddress: master:8042, Resource: <memory:1024, vCores:1>, Priority: 10, Token: Token { kind: ContainerToken, service: 192.168.56.178:37691 }, ] queue=default: capacity=1.0, absoluteCapacity=1.0, usedResources=<memory:2048, vCores:1>, usedCapacity=0.25, absoluteUsedCapacity=0.25, numApps=1, numContainers=1 cluster=<memory:8192, vCores:8>
2017-06-18 11:59:45,512 INFO org.apache.hadoop.yarn.server.resourcemanager.scheduler.capacity.ParentQueue: completedContainer queue=root usedCapacity=0.25 absoluteUsedCapacity=0.25 used=<memory:2048, vCores:1> cluster=<memory:8192, vCores:8>
2017-06-18 11:59:45,512 INFO org.apache.hadoop.yarn.server.resourcemanager.scheduler.capacity.ParentQueue: Re-sorting completed queue: root.default stats: default: capacity=1.0, absoluteCapacity=1.0, usedResources=<memory:2048, vCores:1>, usedCapacity=0.25, absoluteUsedCapacity=0.25, numApps=1, numContainers=1
2017-06-18 11:59:45,512 INFO org.apache.hadoop.yarn.server.resourcemanager.scheduler.capacity.CapacityScheduler: Application attempt appattempt_1497757920083_0003_000001 released container container_1497757920083_0003_01_000003 on node: host: master:37691 #containers=1 available=6144 used=2048 with event: FINISHED
2017-06-18 11:59:46,161 INFO org.apache.hadoop.yarn.server.resourcemanager.rmapp.attempt.RMAppAttemptImpl: Updating application attempt appattempt_1497757920083_0003_000001 with final state: FINISHING, and exit status: -1000
2017-06-18 11:59:46,161 INFO org.apache.hadoop.yarn.server.resourcemanager.rmapp.attempt.RMAppAttemptImpl: appattempt_1497757920083_0003_000001 State change from RUNNING to FINAL_SAVING
2017-06-18 11:59:46,162 INFO org.apache.hadoop.yarn.server.resourcemanager.rmapp.RMAppImpl: Updating application application_1497757920083_0003 with final state: FINISHING
2017-06-18 11:59:46,162 INFO org.apache.hadoop.yarn.server.resourcemanager.rmapp.RMAppImpl: application_1497757920083_0003 State change from RUNNING to FINAL_SAVING
2017-06-18 11:59:46,162 INFO org.apache.hadoop.yarn.server.resourcemanager.recovery.RMStateStore: Updating info for app: application_1497757920083_0003
2017-06-18 11:59:46,162 INFO org.apache.hadoop.yarn.server.resourcemanager.rmapp.attempt.RMAppAttemptImpl: appattempt_1497757920083_0003_000001 State change from FINAL_SAVING to FINISHING
2017-06-18 11:59:46,162 INFO org.apache.hadoop.yarn.server.resourcemanager.rmapp.RMAppImpl: application_1497757920083_0003 State change from FINAL_SAVING to FINISHING
2017-06-18 11:59:47,169 INFO org.apache.hadoop.yarn.server.resourcemanager.ApplicationMasterService: application_1497757920083_0003 unregistered successfully. 
2017-06-18 11:59:52,339 INFO org.apache.hadoop.yarn.server.resourcemanager.rmcontainer.RMContainerImpl: container_1497757920083_0003_01_000001 Container Transitioned from RUNNING to COMPLETED
2017-06-18 11:59:52,339 INFO org.apache.hadoop.yarn.server.resourcemanager.scheduler.common.fica.FiCaSchedulerApp: Completed container: container_1497757920083_0003_01_000001 in state: COMPLETED event:FINISHED
2017-06-18 11:59:52,339 INFO org.apache.hadoop.yarn.server.resourcemanager.RMAuditLogger: USER=root	OPERATION=AM Released Container	TARGET=SchedulerApp	RESULT=SUCCESS	APPID=application_1497757920083_0003	CONTAINERID=container_1497757920083_0003_01_000001
2017-06-18 11:59:52,339 INFO org.apache.hadoop.yarn.server.resourcemanager.scheduler.SchedulerNode: Released container container_1497757920083_0003_01_000001 of capacity <memory:2048, vCores:1> on host master:37691, which currently has 0 containers, <memory:0, vCores:0> used and <memory:8192, vCores:8> available, release resources=true
2017-06-18 11:59:52,340 INFO org.apache.hadoop.yarn.server.resourcemanager.scheduler.capacity.LeafQueue: default used=<memory:0, vCores:0> numContainers=0 user=root user-resources=<memory:0, vCores:0>
2017-06-18 11:59:52,340 INFO org.apache.hadoop.yarn.server.resourcemanager.scheduler.capacity.LeafQueue: completedContainer container=Container: [ContainerId: container_1497757920083_0003_01_000001, NodeId: master:37691, NodeHttpAddress: master:8042, Resource: <memory:2048, vCores:1>, Priority: 0, Token: Token { kind: ContainerToken, service: 192.168.56.178:37691 }, ] queue=default: capacity=1.0, absoluteCapacity=1.0, usedResources=<memory:0, vCores:0>, usedCapacity=0.0, absoluteUsedCapacity=0.0, numApps=1, numContainers=0 cluster=<memory:8192, vCores:8>
2017-06-18 11:59:52,340 INFO org.apache.hadoop.yarn.server.resourcemanager.scheduler.capacity.ParentQueue: completedContainer queue=root usedCapacity=0.0 absoluteUsedCapacity=0.0 used=<memory:0, vCores:0> cluster=<memory:8192, vCores:8>
2017-06-18 11:59:52,340 INFO org.apache.hadoop.yarn.server.resourcemanager.scheduler.capacity.ParentQueue: Re-sorting completed queue: root.default stats: default: capacity=1.0, absoluteCapacity=1.0, usedResources=<memory:0, vCores:0>, usedCapacity=0.0, absoluteUsedCapacity=0.0, numApps=1, numContainers=0
2017-06-18 11:59:52,340 INFO org.apache.hadoop.yarn.server.resourcemanager.scheduler.capacity.CapacityScheduler: Application attempt appattempt_1497757920083_0003_000001 released container container_1497757920083_0003_01_000001 on node: host: master:37691 #containers=0 available=8192 used=0 with event: FINISHED
2017-06-18 11:59:52,340 INFO org.apache.hadoop.yarn.server.resourcemanager.ApplicationMasterService: Unregistering app attempt : appattempt_1497757920083_0003_000001
2017-06-18 11:59:52,341 INFO org.apache.hadoop.yarn.server.resourcemanager.security.AMRMTokenSecretManager: Application finished, removing password for appattempt_1497757920083_0003_000001
2017-06-18 11:59:52,341 INFO org.apache.hadoop.yarn.server.resourcemanager.rmapp.attempt.RMAppAttemptImpl: appattempt_1497757920083_0003_000001 State change from FINISHING to FINISHED
2017-06-18 11:59:52,341 INFO org.apache.hadoop.yarn.server.resourcemanager.rmapp.RMAppImpl: application_1497757920083_0003 State change from FINISHING to FINISHED
2017-06-18 11:59:52,341 INFO org.apache.hadoop.yarn.server.resourcemanager.RMAuditLogger: USER=root	OPERATION=Application Finished - Succeeded	TARGET=RMAppManager	RESULT=SUCCESS	APPID=application_1497757920083_0003
2017-06-18 11:59:52,342 INFO org.apache.hadoop.yarn.server.resourcemanager.RMAppManager$ApplicationSummary: appId=application_1497757920083_0003,name=grep-sort,user=root,queue=default,state=FINISHED,trackingUrl=http://master:8088/proxy/application_1497757920083_0003/,appMasterHost=master,startTime=1497758344507,finishTime=1497758386162,finalStatus=SUCCEEDED
2017-06-18 11:59:52,351 INFO org.apache.hadoop.yarn.server.resourcemanager.scheduler.capacity.CapacityScheduler: Application Attempt appattempt_1497757920083_0003_000001 is done. finalState=FINISHED
2017-06-18 11:59:52,351 INFO org.apache.hadoop.yarn.server.resourcemanager.scheduler.AppSchedulingInfo: Application application_1497757920083_0003 requests cleared
2017-06-18 11:59:52,351 INFO org.apache.hadoop.yarn.server.resourcemanager.scheduler.capacity.LeafQueue: Application removed - appId: application_1497757920083_0003 user: root queue: default #user-pending-applications: 0 #user-active-applications: 0 #queue-pending-applications: 0 #queue-active-applications: 0
2017-06-18 11:59:52,351 INFO org.apache.hadoop.yarn.server.resourcemanager.scheduler.capacity.ParentQueue: Application removed - appId: application_1497757920083_0003 user: root leaf-queue of parent: root #applications: 0
2017-06-18 11:59:52,353 INFO org.apache.hadoop.yarn.server.resourcemanager.amlauncher.AMLauncher: Cleaning master appattempt_1497757920083_0003_000001
2017-06-18 12:01:59,971 INFO org.apache.hadoop.yarn.server.resourcemanager.scheduler.AbstractYarnScheduler: Release request cache is cleaned up
